Workbook

Sheet سوال1
A1: شماره دانشجویی | B1: 40125003 | D1: تقاضا زیاد | E1: تقاضا متوسط | F1: تقاضا کم | G1: وضعیت بازار | U1: A/B | Z1: تقاضا زیاد | AA1: تقاضا متوسط | AB1: تقاضا کم | AC1: وضعیت بازار | AQ1: c | AU1: D
A2: A | B2: 750 | D2: =0.3-0.2*$B$4 -> 0.24 | E2: =0.3+0.5*$B$4 -> 0.45 | F2: =0.4-0.3*$B$4 -> 0.31 | G2: احتمال وقوع | Z2: =0.3-0.2*$B$4 -> 0.24 | AA2: =0.3+0.5*$B$4 -> 0.45 | AB2: =0.4-0.3*$B$4 -> 0.31 | AC2: احتمال وقوع
A3: B | B3: 300 | D3: =2*$B$2+2*$B$3 -> 2100 | E3: =2*$B$2 -> 1500 | F3: =$B$2+$B$3 -> 1050 | G3: محصول نوع 1 | Z3: =D3*1.3 -> 2730 | AA3: =E3*1.3 -> 1950 | AB3: =F3*1.3 -> 1365 | AC3: محصول نوع 1
A4: C | B4: 0.3 | D4: =2*$B$2+3*$B$3 -> 2400 | E4: =$B$2 -> 750 | F4: =$B$2+2*$B$3 -> 1350 | G4: محصول نوع 2 | Z4: =D4*1.3 -> 3120 | AA4: =E4*1.3 -> 975 | AB4: =F4*1.3 -> 1755 | AC4: محصول نوع 2
D5: =3*$B$2+2*$B$3 -> 2850 | E5: =2*$B$2 -> 1500 | F5: =$B$2+3*$B$3 -> 1650 | G5: محصول نوع 3 | Z5: =D5*1.3 -> 3705 | AA5: =E5*1.3 -> 1950 | AB5: =F5*1.3 -> 2145 | AC5: محصول نوع 3 | AT5: مدیر تولید(بخش ج) | AU5: مدیر بازاریابی
A6: Reza Eskandari | D6: =2*$B$2+$B$3 -> 1800 | E6: =$B$2 -> 750 | F6: =$B$2+1.5*$B$3 -> 1200 | G6: محصول نوع 4 | Z6: =D6*0.7 -> 1260 | AA6: =E6*0.7 -> 525 | AB6: =F6*0.7 -> 840 | AC6: محصول نوع 4 | AT6: 3 | AU6: 3 or 6 | AV6: بدبینانه | AW6: روش انتخاب
D7: =2*$B$2+4*$B$3 -> 2700 | E7: =1.5*$B$2 -> 1125 | F7: =$B$2+2.5*$B$3 -> 1500 | G7: محصول نوع 5 | Z7: =D7*0.7 -> 1890 | AA7: =E7*0.7 -> 787.5 | AB7: =F7*0.7 -> 1050 | AC7: محصول نوع 5 | AT7: 3 | AU7: 3 or 6 | AV7: خوشبینانه
D8: =3*$B$2+2*$B$3 -> 2850 | E8: =2*$B$2 -> 1500 | F8: =$B$2+3.5*$B$3 -> 1800 | G8: محصول نوع 6 | Z8: =D8*0.7 -> 1995 | AA8: =E8*0.7 -> 1050 | AB8: =F8*0.7 -> 1260 | AC8: محصول نوع 6 | AT8: 3 | AU8: 3 or 6 | AV8: هارویز
K9: الف | V9: ب | AG9: الف | AR9: ب | AT9: 1 | AU9: 6 | AV9: حداقل پشیمانی
E10: =E1 -> تقاضا متوسط | F10: =F1 -> تقاضا کم | G10: =G1 -> وضعیت بازار | I10: =D1 -> تقاضا زیاد | J10: =E1 -> تقاضا متوسط | K10: =F1 -> تقاضا کم | L10: =G1 -> وضعیت بازار | P10: =D1 -> تقاضا زیاد | Q10: =E1 -> تقاضا متوسط | R10: =F1 -> تقاضا کم | S10: =G1 -> وضعیت بازار | T10: امید ریاضی | AA10: =AA1 -> تقاضا متوسط | AB10: =AB1 -> تقاضا کم | AC10: =AC1 -> وضعیت بازار | AE10: =Z1 -> تقاضا زیاد | AF10: =AA1 -> تقاضا متوسط | AG10: =AB1 -> تقاضا کم | AH10: =AC1 -> وضعیت بازار | AL10: =Z1 -> تقاضا زیاد | AM10: =AA1 -> تقاضا متوسط | AN10: =AB1 -> تقاضا کم | AO10: =AC1 -> وضعیت بازار | AP10: امید ریاضی | AT10: 3 | AU10: 6 | AV10: لاپلاس
D11: =D2 -> 0.24 | E11: =E2 -> 0.45 | F11: =F2 -> 0.31 | G11: =G2 -> احتمال وقوع | I11: =D2 -> 0.24 | J11: =E2 -> 0.45 | K11: =F2 -> 0.31 | L11: =G2 -> احتمال وقوع | P11: =D2 -> 0.24 | Q11: =E2 -> 0.45 | R11: =F2 -> 0.31 | S11: =G2 -> احتمال وقوع | Z11: =Z2 -> 0.24 | AA11: =AA2 -> 0.45 | AB11: =AB2 -> 0.31 | AC11: =AC2 -> احتمال وقوع | AE11: =Z2 -> 0.24 | AF11: =AA2 -> 0.45 | AG11: =AB2 -> 0.31 | AH11: =AC2 -> احتمال وقوع | AL11: =Z2 -> 0.24 | AM11: =AA2 -> 0.45 | AN11: =AB2 -> 0.31 | AO11: =AC2 -> احتمال وقوع | AT11: 6 | AU11: 6 | AV11: بیز
A12: بدبینانه | D12: =D3 -> 2100 | E12: =E3 -> 1500 | F12: =F3 -> 1050 | G12: =G3 -> محصول نوع 1 | I12: =D3 -> 2100 | J12: =E3 -> 1500 | K12: =F3 -> 1050 | L12: =G3 -> محصول نوع 1 | P12: =D3 -> 2100 | Q12: =E3 -> 1500 | R12: =F3 -> 1050 | S12: =G3 -> محصول نوع 1 | T12: =R12*$R$11+Q12*$Q$11+P12*$P$11 -> 1504.5 | W12: بدبینانه | Z12: =Z3 -> 2730 | AA12: =AA3 -> 1950 | AB12: =AB3 -> 1365 | AC12: =AC3 -> محصول نوع 1 | AE12: =Z3 -> 2730 | AF12: =AA3 -> 1950 | AG12: =AB3 -> 1365 | AH12: =AC3 -> محصول نوع 1 | AL12: =Z3 -> 2730 | AM12: =AA3 -> 1950 | AN12: =AB3 -> 1365 | AO12: =AC3 -> محصول نوع 1 | AP12: =AN12*$R$11+AM12*$Q$11+AL12*$P$11 -> 1955.85
A13: Max i min j Oij | D13: =D4 -> 2400 | E13: =E4 -> 750 | F13: =F4 -> 1350 | G13: =G4 -> محصول نوع 2 | I13: =D4 -> 2400 | J13: =E4 -> 750 | K13: =F4 -> 1350 | L13: =G4 -> محصول نوع 2 | M13: محصول نوع 3 یا 6 انتخاب میشود | P13: =D4 -> 2400 | Q13: =E4 -> 750 | R13: =F4 -> 1350 | S13: =G4 -> محصول نوع 2 | T13: =R13*$R$11+Q13*$Q$11+P13*$P$11 -> 1332 | U13: محصول 6 انتخاب میشود | W13: Max i min j Oij | Z13: =Z4 -> 3120 | AA13: =AA4 -> 975 | AB13: =AB4 -> 1755 | AC13: =AC4 -> محصول نوع 2 | AE13: =Z4 -> 3120 | AF13: =AA4 -> 975 | AG13: =AB4 -> 1755 | AH13: =AC4 -> محصول نوع 2 | AI13: محصول نوع 3 انتخاب میشود | AL13: =Z4 -> 3120 | AM13: =AA4 -> 975 | AN13: =AB4 -> 1755 | AO13: =AC4 -> محصول نوع 2 | AP13: =AN13*$R$11+AM13*$Q$11+AL13*$P$11 -> 1731.6 | AQ13: محصول 6 انتخاب میشود
D14: =D5 -> 2850 | E14: =E5 -> 1500 | F14: =F5 -> 1650 | G14: =G5 -> محصول نوع 3 | I14: =D5 -> 2850 | J14: =E5 -> 1500 | K14: =F5 -> 1650 | L14: =G5 -> محصول نوع 3 | P14: =D5 -> 2850 | Q14: =E5 -> 1500 | R14: =F5 -> 1650 | S14: =G5 -> محصول نوع 3 | T14: =R14*$R$11+Q14*$Q$11+P14*$P$11 -> 1870.5 | Z14: =Z5 -> 3705 | AA14: =AA5 -> 1950 | AB14: =AB5 -> 2145 | AC14: =AC5 -> محصول نوع 3 | AE14: =Z5 -> 3705 | AF14: =AA5 -> 1950 | AG14: =AB5 -> 2145 | AH14: =AC5 -> محصول نوع 3 | AL14: =Z5 -> 3705 | AM14: =AA5 -> 1950 | AN14: =AB5 -> 2145 | AO14: =AC5 -> محصول نوع 3 | AP14: =AN14*$R$11+AM14*$Q$11+AL14*$P$11 -> 2431.65
D15: =D6 -> 1800 | E15: =E6 -> 750 | F15: =F6 -> 1200 | G15: =G6 -> محصول نوع 4 | I15: =D6 -> 1800 | J15: =E6 -> 750 | K15: =F6 -> 1200 | L15: =G6 -> محصول نوع 4 | P15: =D6 -> 1800 | Q15: =E6 -> 750 | R15: =F6 -> 1200 | S15: =G6 -> محصول نوع 4 | T15: =R15*$R$11+Q15*$Q$11+P15*$P$11 -> 1141.5 | Z15: =Z6 -> 1260 | AA15: =AA6 -> 525 | AB15: =AB6 -> 840 | AC15: =AC6 -> محصول نوع 4 | AE15: =Z6 -> 1260 | AF15: =AA6 -> 525 | AG15: =AB6 -> 840 | AH15: =AC6 -> محصول نوع 4 | AL15: =Z6 -> 1260 | AM15: =AA6 -> 525 | AN15: =AB6 -> 840 | AO15: =AC6 -> محصول نوع 4 | AP15: =AN15*$R$11+AM15*$Q$11+AL15*$P$11 -> 799.05
D16: =D7 -> 2700 | E16: =E7 -> 1125 | F16: =F7 -> 1500 | G16: =G7 -> محصول نوع 5 | I16: =D7 -> 2700 | J16: =E7 -> 1125 | K16: =F7 -> 1500 | L16: =G7 -> محصول نوع 5 | P16: =D7 -> 2700 | Q16: =E7 -> 1125 | R16: =F7 -> 1500 | S16: =G7 -> محصول نوع 5 | T16: =R16*$R$11+Q16*$Q$11+P16*$P$11 -> 1619.25 | Z16: =Z7 -> 1890 | AA16: =AA7 -> 787.5 | AB16: =AB7 -> 1050 | AC16: =AC7 -> محصول نوع 5 | AE16: =Z7 -> 1890 | AF16: =AA7 -> 787.5 | AG16: =AB7 -> 1050 | AH16: =AC7 -> محصول نوع 5 | AL16: =Z7 -> 1890 | AM16: =AA7 -> 787.5 | AN16: =AB7 -> 1050 | AO16: =AC7 -> محصول نوع 5 | AP16: =AN16*$R$11+AM16*$Q$11+AL16*$P$11 -> 1133.475
D17: =D8 -> 2850 | E17: =E8 -> 1500 | F17: =F8 -> 1800 | G17: =G8 -> محصول نوع 6 | I17: =D8 -> 2850 | J17: =E8 -> 1500 | K17: =F8 -> 1800 | L17: =G8 -> محصول نوع 6 | P17: =D8 -> 2850 | Q17: =E8 -> 1500 | R17: =F8 -> 1800 | S17: =G8 -> محصول نوع 6 | T17: =R17*$R$11+Q17*$Q$11+P17*$P$11 -> 1917 | Z17: =Z8 -> 1995 | AA17: =AA8 -> 1050 | AB17: =AB8 -> 1260 | AC17: =AC8 -> محصول نوع 6 | AE17: =Z8 -> 1995 | AF17: =AA8 -> 1050 | AG17: =AB8 -> 1260 | AH17: =AC8 -> محصول نوع 6 | AL17: =Z8 -> 1995 | AM17: =AA8 -> 1050 | AN17: =AB8 -> 1260 | AO17: =AC8 -> محصول نوع 6 | AP17: =AN17*$R$11+AM17*$Q$11+AL17*$P$11 -> 1341.9
D19: =D1 -> تقاضا زیاد | E19: =E1 -> تقاضا متوسط | F19: =F1 -> تقاضا کم | G19: =G1 -> وضعیت بازار | I19: =D1 -> تقاضا زیاد | J19: =E1 -> تقاضا متوسط | K19: =F1 -> تقاضا کم | L19: =G1 -> وضعیت بازار | Z19: =Z1 -> تقاضا زیاد | AA19: =AA1 -> تقاضا متوسط | AB19: =AB1 -> تقاضا کم | AC19: =AC1 -> وضعیت بازار | AE19: =Z1 -> تقاضا زیاد | AF19: =AA1 -> تقاضا متوسط | AG19: =AB1 -> تقاضا کم | AH19: =AC1 -> وضعیت بازار
D20: =D2 -> 0.24 | E20: =E2 -> 0.45 | F20: =F2 -> 0.31 | G20: =G2 -> احتمال وقوع | I20: =D2 -> 0.24 | J20: =E2 -> 0.45 | K20: =F2 -> 0.31 | L20: =G2 -> احتمال وقوع | Z20: =Z2 -> 0.24 | AA20: =AA2 -> 0.45 | AB20: =AB2 -> 0.31 | AC20: =AC2 -> احتمال وقوع | AE20: =Z2 -> 0.24 | AF20: =AA2 -> 0.45 | AG20: =AB2 -> 0.31 | AH20: =AC2 -> احتمال وقوع
A21: خوشبینانه | D21: =D3 -> 2100 | E21: =E3 -> 1500 | F21: =F3 -> 1050 | G21: =G3 -> محصول نوع 1 | I21: =D3 -> 2100 | J21: =E3 -> 1500 | K21: =F3 -> 1050 | L21: =G3 -> محصول نوع 1 | M21: محصول نوع 3 یا 6 انتخاب میشوند | W21: خوشبینانه | Z21: =Z3 -> 2730 | AA21: =AA3 -> 1950 | AB21: =AB3 -> 1365 | AC21: =AC3 -> محصول نوع 1 | AE21: =Z3 -> 2730 | AF21: =AA3 -> 1950 | AG21: =AB3 -> 1365 | AH21: =AC3 -> محصول نوع 1 | AI21: محصول نوع 3 انتخاب میشود
A22: Max i max j Oij | D22: =D4 -> 2400 | E22: =E4 -> 750 | F22: =F4 -> 1350 | G22: =G4 -> محصول نوع 2 | I22: =D4 -> 2400 | J22: =E4 -> 750 | K22: =F4 -> 1350 | L22: =G4 -> محصول نوع 2 | W22: Max i max j Oij | Z22: =Z4 -> 3120 | AA22: =AA4 -> 975 | AB22: =AB4 -> 1755 | AC22: =AC4 -> محصول نوع 2 | AE22: =Z4 -> 3120 | AF22: =AA4 -> 975 | AG22: =AB4 -> 1755 | AH22: =AC4 -> محصول نوع 2
D23: =D5 -> 2850 | E23: =E5 -> 1500 | F23: =F5 -> 1650 | G23: =G5 -> محصول نوع 3 | I23: =D5 -> 2850 | J23: =E5 -> 1500 | K23: =F5 -> 1650 | L23: =G5 -> محصول نوع 3 | Z23: =Z5 -> 3705 | AA23: =AA5 -> 1950 | AB23: =AB5 -> 2145 | AC23: =AC5 -> محصول نوع 3 | AE23: =Z5 -> 3705 | AF23: =AA5 -> 1950 | AG23: =AB5 -> 2145 | AH23: =AC5 -> محصول نوع 3
D24: =D6 -> 1800 | E24: =E6 -> 750 | F24: =F6 -> 1200 | G24: =G6 -> محصول نوع 4 | I24: =D6 -> 1800 | J24: =E6 -> 750 | K24: =F6 -> 1200 | L24: =G6 -> محصول نوع 4 | Z24: =Z6 -> 1260 | AA24: =AA6 -> 525 | AB24: =AB6 -> 840 | AC24: =AC6 -> محصول نوع 4 | AE24: =Z6 -> 1260 | AF24: =AA6 -> 525 | AG24: =AB6 -> 840 | AH24: =AC6 -> محصول نوع 4
D25: =D7 -> 2700 | E25: =E7 -> 1125 | F25: =F7 -> 1500 | G25: =G7 -> محصول نوع 5 | I25: =D7 -> 2700 | J25: =E7 -> 1125 | K25: =F7 -> 1500 | L25: =G7 -> محصول نوع 5 | Z25: =Z7 -> 1890 | AA25: =AA7 -> 787.5 | AB25: =AB7 -> 1050 | AC25: =AC7 -> محصول نوع 5 | AE25: =Z7 -> 1890 | AF25: =AA7 -> 787.5 | AG25: =AB7 -> 1050 | AH25: =AC7 -> محصول نوع 5
D26: =D8 -> 2850 | E26: =E8 -> 1500 | F26: =F8 -> 1800 | G26: =G8 -> محصول نوع 6 | I26: =D8 -> 2850 | J26: =E8 -> 1500 | K26: =F8 -> 1800 | L26: =G8 -> محصول نوع 6 | Z26: =Z8 -> 1995 | AA26: =AA8 -> 1050 | AB26: =AB8 -> 1260 | AC26: =AC8 -> محصول نوع 6 | AE26: =Z8 -> 1995 | AF26: =AA8 -> 1050 | AG26: =AB8 -> 1260 | AH26: =AC8 -> محصول نوع 6
F28: ALPHA | AB28: ALPHA
F29: 0.7 | G29: 0.2 | H29: گزینه | AB29: 0.7 | AC29: 0.2 | AD29: گزینه
A30: هارویز | F30: =$F$29*MAX(D3:F3)+(1-$F$29)*MIN(D3:F3) -> 1785 | G30: =$G$29*MAX(D3:F3)+(1-$G$29)*MIN(D3:F3) -> 1260 | H30: محصول نوع 1 | K30: محصول نوع 3 یا 6 انتخاب میشوند | W30: هارویز | AB30: =$F$29*MAX(Z3:AB3)+(1-$F$29)*MIN(Z3:AB3) -> 2320.5 | AC30: =$G$29*MAX(Z3:AB3)+(1-$G$29)*MIN(Z3:AB3) -> 1638 | AD30: محصول نوع 1
F31: =$F$29*MAX(D4:F4)+(1-$F$29)*MIN(D4:F4) -> 1905 | G31: =$G$29*MAX(D4:F4)+(1-$G$29)*MIN(D4:F4) -> 1080 | H31: محصول نوع 2 | AB31: =$F$29*MAX(Z4:AB4)+(1-$F$29)*MIN(Z4:AB4) -> 2476.5 | AC31: =$G$29*MAX(Z4:AB4)+(1-$G$29)*MIN(Z4:AB4) -> 1404 | AD31: محصول نوع 2 | AG31: محصول نوع 3 انتخاب میشود
F32: =$F$29*MAX(D5:F5)+(1-$F$29)*MIN(D5:F5) -> 2445 | G32: =$G$29*MAX(D5:F5)+(1-$G$29)*MIN(D5:F5) -> 1770 | H32: محصول نوع 3 | AB32: =$F$29*MAX(Z5:AB5)+(1-$F$29)*MIN(Z5:AB5) -> 3178.5 | AC32: =$G$29*MAX(Z5:AB5)+(1-$G$29)*MIN(Z5:AB5) -> 2301 | AD32: محصول نوع 3
F33: =$F$29*MAX(D6:F6)+(1-$F$29)*MIN(D6:F6) -> 1485 | G33: =$G$29*MAX(D6:F6)+(1-$G$29)*MIN(D6:F6) -> 960 | H33: محصول نوع 4 | AB33: =$F$29*MAX(Z6:AB6)+(1-$F$29)*MIN(Z6:AB6) -> 1039.5 | AC33: =$G$29*MAX(Z6:AB6)+(1-$G$29)*MIN(Z6:AB6) -> 672 | AD33: محصول نوع 4
F34: =$F$29*MAX(D7:F7)+(1-$F$29)*MIN(D7:F7) -> 2227.5 | G34: =$G$29*MAX(D7:F7)+(1-$G$29)*MIN(D7:F7) -> 1440 | H34: محصول نوع 5 | AB34: =$F$29*MAX(Z7:AB7)+(1-$F$29)*MIN(Z7:AB7) -> 1559.25 | AC34: =$G$29*MAX(Z7:AB7)+(1-$G$29)*MIN(Z7:AB7) -> 1008 | AD34: محصول نوع 5
F35: =$F$29*MAX(D8:F8)+(1-$F$29)*MIN(D8:F8) -> 2445 | G35: =$G$29*MAX(D8:F8)+(1-$G$29)*MIN(D8:F8) -> 1770 | H35: محصول نوع 6 | AB35: =$F$29*MAX(Z8:AB8)+(1-$F$29)*MIN(Z8:AB8) -> 1711.5 | AC35: =$G$29*MAX(Z8:AB8)+(1-$G$29)*MIN(Z8:AB8) -> 1239 | AD35: محصول نوع 6
D37: =D1 -> تقاضا زیاد | E37: =E1 -> تقاضا متوسط | F37: =F1 -> تقاضا کم | G37: =G1 -> وضعیت بازار | I37: =D1 -> تقاضا زیاد | J37: =E1 -> تقاضا متوسط | K37: =F1 -> تقاضا کم | L37: =G1 -> وضعیت بازار | Z37: =Z1 -> تقاضا زیاد | AA37: =AA1 -> تقاضا متوسط | AB37: =AB1 -> تقاضا کم | AC37: =AC1 -> وضعیت بازار | AE37: =Z1 -> تقاضا زیاد | AF37: =AA1 -> تقاضا متوسط | AG37: =AB1 -> تقاضا کم | AH37: =AC1 -> وضعیت بازار
D38: =D2 -> 0.24 | E38: =E2 -> 0.45 | F38: =F2 -> 0.31 | G38: =G2 -> احتمال وقوع | I38: =D2 -> 0.24 | J38: =E2 -> 0.45 | K38: =F2 -> 0.31 | L38: =G2 -> احتمال وقوع | Z38: =Z2 -> 0.24 | AA38: =AA2 -> 0.45 | AB38: =AB2 -> 0.31 | AC38: =AC2 -> احتمال وقوع | AE38: =Z2 -> 0.24 | AF38: =AA2 -> 0.45 | AG38: =AB2 -> 0.31 | AH38: =AC2 -> احتمال وقوع
A39: حداقل پشیمانی | D39: =ABS(D3-$D$45) -> 750 | E39: =ABS(E3-$E$45) -> 0 | F39: =ABS(F3-$F$45) -> 750 | G39: =G3 -> محصول نوع 1 | I39: =D39 -> 750 | J39: =E39 -> 0 | K39: =F39 -> 750 | L39: =G3 -> محصول نوع 1 | W39: حداقل پشیمانی | Z39: =ABS(Z3-$D$45) -> 120 | AA39: =ABS(AA3-$E$45) -> 450 | AB39: =ABS(AB3-$F$45) -> 435 | AC39: =AC3 -> محصول نوع 1 | AE39: =Z39 -> 120 | AF39: =AA39 -> 450 | AG39: =AB39 -> 435 | AH39: =AC3 -> محصول نوع 1
A40: min i max j r ij | D40: =ABS(D4-$D$45) -> 450 | E40: =ABS(E4-$E$45) -> 750 | F40: =ABS(F4-$F$45) -> 450 | G40: =G4 -> محصول نوع 2 | I40: =D40 -> 450 | J40: =E40 -> 750 | K40: =F40 -> 450 | L40: =G4 -> محصول نوع 2 | M40: محصول 6 انتخاب میشود | W40: min i max j r ij | Z40: =ABS(Z4-$D$45) -> 270 | AA40: =ABS(AA4-$E$45) -> 525 | AB40: =ABS(AB4-$F$45) -> 45 | AC40: =AC4 -> محصول نوع 2 | AE40: =Z40 -> 270 | AF40: =AA40 -> 525 | AG40: =AB40 -> 45 | AH40: =AC4 -> محصول نوع 2 | AI40: محصول 1 انتخاب میشود
A41: r ij = Oij-Max j Oij | D41: =ABS(D5-$D$45) -> 0 | E41: =ABS(E5-$E$45) -> 0 | F41: =ABS(F5-$F$45) -> 150 | G41: =G5 -> محصول نوع 3 | I41: =D41 -> 0 | J41: =E41 -> 0 | K41: =F41 -> 150 | L41: =G5 -> محصول نوع 3 | W41: r ij = Oij-Max j Oij | Z41: =ABS(Z5-$D$45) -> 855 | AA41: =ABS(AA5-$E$45) -> 450 | AB41: =ABS(AB5-$F$45) -> 345 | AC41: =AC5 -> محصول نوع 3 | AE41: =Z41 -> 855 | AF41: =AA41 -> 450 | AG41: =AB41 -> 345 | AH41: =AC5 -> محصول نوع 3
D42: =ABS(D6-$D$45) -> 1050 | E42: =ABS(E6-$E$45) -> 750 | F42: =ABS(F6-$F$45) -> 600 | G42: =G6 -> محصول نوع 4 | I42: =D42 -> 1050 | J42: =E42 -> 750 | K42: =F42 -> 600 | L42: =G6 -> محصول نوع 4 | Z42: =ABS(Z6-$D$45) -> 1590 | AA42: =ABS(AA6-$E$45) -> 975 | AB42: =ABS(AB6-$F$45) -> 960 | AC42: =AC6 -> محصول نوع 4 | AE42: =Z42 -> 1590 | AF42: =AA42 -> 975 | AG42: =AB42 -> 960 | AH42: =AC6 -> محصول نوع 4
D43: =ABS(D7-$D$45) -> 150 | E43: =ABS(E7-$E$45) -> 375 | F43: =ABS(F7-$F$45) -> 300 | G43: =G7 -> محصول نوع 5 | I43: =D43 -> 150 | J43: =E43 -> 375 | K43: =F43 -> 300 | L43: =G7 -> محصول نوع 5 | Z43: =ABS(Z7-$D$45) -> 960 | AA43: =ABS(AA7-$E$45) -> 712.5 | AB43: =ABS(AB7-$F$45) -> 750 | AC43: =AC7 -> محصول نوع 5 | AE43: =Z43 -> 960 | AF43: =AA43 -> 712.5 | AG43: =AB43 -> 750 | AH43: =AC7 -> محصول نوع 5
...

Sheet سوال2
A1: =سوال1!A1 -> شماره دانشجویی | B1: =سوال1!B1 -> 40125003 | D1: دسترسی به حمل و نقل عمومی | E1: تعداد بوستان در منطقه | F1: میزان ترافیک | G1: دسترسی به بازار خرید | H1: متوسط قیمت خرید | I1: منطقه | K1: برای دو معیار منفی کلامی(دسترسی به بازار خرید و میزان ترافیک) تبدیل صورت گرفته است. به این شکل که میزان ترافیک کم نسبت به ترافیک زیاد عدد بیشتری گرفته و همچنین دسترسی به بازار نزدیک عدد بیشتری نسبت به دسترسی به بازار دور دارد به همین علت این دو معیار را نیز مثبت در نظر میگیریم. لذا تنها معیار منفی متوسط قیمت خرید است
A2: =سوال1!A2 -> A | B2: =سوال1!B2 -> 750 | D2: 7 | E2: 5 | F2: 3 | G2: 7 | H2: =4*B2 -> 3000 | I2: 1
A3: =سوال1!A3 -> B | B3: =سوال1!B3 -> 300 | D3: 9 | E3: 3 | F3: 4 | G3: 3 | H3: =8*B2 -> 6000 | I3: 2
A4: =سوال1!A4 -> C | B4: =سوال1!B4 -> 0.3 | D4: 4 | E4: 4 | F4: 5 | G4: 6 | H4: =9*B2 -> 6750 | I4: 3
D5: 5 | E5: 2 | F5: 7 | G5: 9 | H5: =3*B2 -> 2250 | I5: 4
D6: 3 | E6: 6 | F6: 3 | G6: 4 | H6: =7*B2 -> 5250 | I6: 5
D7: 6 | E7: 4 | F7: 7 | G7: 9 | H7: =6*B2 -> 4500 | I7: 6
D9: دسترسی به حمل و نقل عمومی | E9: تعداد بوستان در منطقه | F9: میزان ترافیک | G9: دسترسی به بازار خرید | H9: متوسط قیمت خرید | I9: منطقه
D10: =D2/SQRT(SUMSQ($D$2:$D$7)) -> 0.47628967 | E10: =E2/SQRT(SUMSQ($E$2:$E$7)) -> 0.48564293 | F10: =F2/SQRT(SUMSQ($F$2:$F$7)) -> 0.23942607 | G10: =G2/SQRT(SUMSQ($G$2:$G$7)) -> 0.42443734 | H10: =H2/SQRT(SUMSQ($H$2:$H$7)) -> 0.25048972 | I10: 1
B11: نرم اقلیدوسی | D11: =D3/SQRT(SUMSQ($D$2:$D$7)) -> 0.61237244 | E11: =E3/SQRT(SUMSQ($E$2:$E$7)) -> 0.29138576 | F11: =F3/SQRT(SUMSQ($F$2:$F$7)) -> 0.31923475 | G11: =G3/SQRT(SUMSQ($G$2:$G$7)) -> 0.18190172 | H11: =H3/SQRT(SUMSQ($H$2:$H$7)) -> 0.50097943 | I11: 2
D12: =D4/SQRT(SUMSQ($D$2:$D$7)) -> 0.27216553 | E12: =E4/SQRT(SUMSQ($E$2:$E$7)) -> 0.38851434 | F12: =F4/SQRT(SUMSQ($F$2:$F$7)) -> 0.39904344 | G12: =G4/SQRT(SUMSQ($G$2:$G$7)) -> 0.36380344 | H12: =H4/SQRT(SUMSQ($H$2:$H$7)) -> 0.56360186 | I12: 3
D13: =D5/SQRT(SUMSQ($D$2:$D$7)) -> 0.34020691 | E13: =E5/SQRT(SUMSQ($E$2:$E$7)) -> 0.19425717 | F13: =F5/SQRT(SUMSQ($F$2:$F$7)) -> 0.55866082 | G13: =G5/SQRT(SUMSQ($G$2:$G$7)) -> 0.54570516 | H13: =H5/SQRT(SUMSQ($H$2:$H$7)) -> 0.18786729 | I13: 4
D14: =D6/SQRT(SUMSQ($D$2:$D$7)) -> 0.20412415 | E14: =E6/SQRT(SUMSQ($E$2:$E$7)) -> 0.58277152 | F14: =F6/SQRT(SUMSQ($F$2:$F$7)) -> 0.23942607 | G14: =G6/SQRT(SUMSQ($G$2:$G$7)) -> 0.24253563 | H14: =H6/SQRT(SUMSQ($H$2:$H$7)) -> 0.438357 | I14: 5
D15: =D7/SQRT(SUMSQ($D$2:$D$7)) -> 0.40824829 | E15: =E7/SQRT(SUMSQ($E$2:$E$7)) -> 0.38851434 | F15: =F7/SQRT(SUMSQ($F$2:$F$7)) -> 0.55866082 | G15: =G7/SQRT(SUMSQ($G$2:$G$7)) -> 0.54570516 | H15: =H7/SQRT(SUMSQ($H$2:$H$7)) -> 0.37573457 | I15: 6
D17: دسترسی به حمل و نقل عمومی | E17: تعداد بوستان در منطقه | F17: میزان ترافیک | G17: دسترسی به بازار خرید | H17: متوسط قیمت خرید | I17: منطقه
D18: =D2/SUM(D$2:D$7) -> 0.20588235 | E18: =E2/SUM($E$2:$E$7) -> 0.20833333 | F18: =F2/SUM($F$2:$F$7) -> 0.10344828 | G18: =G2/SUM($G$2:$G$7) -> 0.18421053 | H18: =(1/H2)/SUMPRODUCT(1/$H$2:$H$7) -> 0.22144112 | I18: 1
B19: نرم ساده | D19: =D3/SUM($D$2:$D$7) -> 0.26470588 | E19: =E3/SUM($E$2:$E$7) -> 0.125 | F19: =F3/SUM($F$2:$F$7) -> 0.13793103 | G19: =G3/SUM($G$2:$G$7) -> 0.078947368 | H19: =(1/H3)/SUMPRODUCT(1/$H$2:$H$7) -> 0.11072056 | I19: 2
D20: =D4/SUM($D$2:$D$7) -> 0.11764706 | E20: =E4/SUM($E$2:$E$7) -> 0.16666667 | F20: =F4/SUM($F$2:$F$7) -> 0.17241379 | G20: =G4/SUM($G$2:$G$7) -> 0.15789474 | H20: =(1/H4)/SUMPRODUCT(1/$H$2:$H$7) -> 0.098418278 | I20: 3
D21: =D5/SUM($D$2:$D$7) -> 0.14705882 | E21: =E5/SUM($E$2:$E$7) -> 0.083333333 | F21: =F5/SUM($F$2:$F$7) -> 0.24137931 | G21: =G5/SUM($G$2:$G$7) -> 0.23684211 | H21: =(1/H5)/SUMPRODUCT(1/$H$2:$H$7) -> 0.29525483 | I21: 4
D22: =D6/SUM($D$2:$D$7) -> 0.088235294 | E22: =E6/SUM($E$2:$E$7) -> 0.25 | F22: =F6/SUM($F$2:$F$7) -> 0.10344828 | G22: =G6/SUM($G$2:$G$7) -> 0.10526316 | H22: =(1/H6)/SUMPRODUCT(1/$H$2:$H$7) -> 0.12653779 | I22: 5
D23: =D7/SUM($D$2:$D$7) -> 0.17647059 | E23: =E7/SUM($E$2:$E$7) -> 0.16666667 | F23: =F7/SUM($F$2:$F$7) -> 0.24137931 | G23: =G7/SUM($G$2:$G$7) -> 0.23684211 | H23: =(1/H7)/SUMPRODUCT(1/$H$2:$H$7) -> 0.14762742 | I23: 6
D25: دسترسی به حمل و نقل عمومی | E25: تعداد بوستان در منطقه | F25: میزان ترافیک | G25: دسترسی به بازار خرید | H25: متوسط قیمت خرید | I25: منطقه
D26: =D2/MAX($D$2:$D$7) -> 0.77777778 | E26: =E2/MAX($E$2:$E$7) -> 0.83333333 | F26: =F2/MAX($F$2:$F$7) -> 0.42857143 | G26: =G2/MAX($G$2:$G$7) -> 0.77777778 | H26: =MIN($H$2:$H$7)/H2 -> 0.75 | I26: 1
B27: روش خطی | D27: =D3/MAX($D$2:$D$7) -> 1 | E27: =E3/MAX($E$2:$E$7) -> 0.5 | F27: =F3/MAX($F$2:$F$7) -> 0.57142857 | G27: =G3/MAX($G$2:$G$7) -> 0.33333333 | H27: =MIN($H$2:$H$7)/H3 -> 0.375 | I27: 2
D28: =D4/MAX($D$2:$D$7) -> 0.44444444 | E28: =E4/MAX($E$2:$E$7) -> 0.66666667 | F28: =F4/MAX($F$2:$F$7) -> 0.71428571 | G28: =G4/MAX($G$2:$G$7) -> 0.66666667 | H28: =MIN($H$2:$H$7)/H4 -> 0.33333333 | I28: 3
D29: =D5/MAX($D$2:$D$7) -> 0.55555556 | E29: =E5/MAX($E$2:$E$7) -> 0.33333333 | F29: =F5/MAX($F$2:$F$7) -> 1 | G29: =G5/MAX($G$2:$G$7) -> 1 | H29: =MIN($H$2:$H$7)/H5 -> 1 | I29: 4
D30: =D6/MAX($D$2:$D$7) -> 0.33333333 | E30: =E6/MAX($E$2:$E$7) -> 1 | F30: =F6/MAX($F$2:$F$7) -> 0.42857143 | G30: =G6/MAX($G$2:$G$7) -> 0.44444444 | H30: =MIN($H$2:$H$7)/H6 -> 0.42857143 | I30: 5
D31: =D7/MAX($D$2:$D$7) -> 0.66666667 | E31: =E7/MAX($E$2:$E$7) -> 0.66666667 | F31: =F7/MAX($F$2:$F$7) -> 1 | G31: =G7/MAX($G$2:$G$7) -> 1 | H31: =MIN($H$2:$H$7)/H7 -> 0.5 | I31: 6
D33: دسترسی به حمل و نقل عمومی | E33: تعداد بوستان در منطقه | F33: میزان ترافیک | G33: دسترسی به بازار خرید | H33: متوسط قیمت خرید | I33: منطقه
D34: =(D2-MIN($D$2:$D$7))/(MAX($D$2:$D$7)-MIN($D$2:$D$7)) -> 0.66666667 | E34: =(E2-MIN($E$2:$E$7))/(MAX($E$2:$E$7)-MIN($E$2:$E$7)) -> 0.75 | F34: =(F2-MIN($F$2:$F$7))/(MAX($F$2:$F$7)-MIN($F$2:$F$7)) -> 0 | G34: =(G2-MIN($G$2:$G$7))/(MAX($G$2:$G$7)-MIN($G$2:$G$7)) -> 0.66666667 | H34: =(MAX($H$2:$H$7)-H2)/(MAX($H$2:$H$7)-MIN($H$2:$H$7)) -> 0.83333333 | I34: 1
B35: فاصله ای (فازی) | D35: =(D3-MIN($D$2:$D$7))/(MAX($D$2:$D$7)-MIN($D$2:$D$7)) -> 1 | E35: =(E3-MIN($E$2:$E$7))/(MAX($E$2:$E$7)-MIN($E$2:$E$7)) -> 0.25 | F35: =(F3-MIN($F$2:$F$7))/(MAX($F$2:$F$7)-MIN($F$2:$F$7)) -> 0.25 | G35: =(G3-MIN($G$2:$G$7))/(MAX($G$2:$G$7)-MIN($G$2:$G$7)) -> 0 | H35: =(MAX($H$2:$H$7)-H3)/(MAX($H$2:$H$7)-MIN($H$2:$H$7)) -> 0.16666667 | I35: 2
D36: =(D4-MIN($D$2:$D$7))/(MAX($D$2:$D$7)-MIN($D$2:$D$7)) -> 0.16666667 | E36: =(E4-MIN($E$2:$E$7))/(MAX($E$2:$E$7)-MIN($E$2:$E$7)) -> 0.5 | F36: =(F4-MIN($F$2:$F$7))/(MAX($F$2:$F$7)-MIN($F$2:$F$7)) -> 0.5 | G36: =(G4-MIN($G$2:$G$7))/(MAX($G$2:$G$7)-MIN($G$2:$G$7)) -> 0.5 | H36: =(MAX($H$2:$H$7)-H4)/(MAX($H$2:$H$7)-MIN($H$2:$H$7)) -> 0 | I36: 3
D37: =(D5-MIN($D$2:$D$7))/(MAX($D$2:$D$7)-MIN($D$2:$D$7)) -> 0.33333333 | E37: =(E5-MIN($E$2:$E$7))/(MAX($E$2:$E$7)-MIN($E$2:$E$7)) -> 0 | F37: =(F5-MIN($F$2:$F$7))/(MAX($F$2:$F$7)-MIN($F$2:$F$7)) -> 1 | G37: =(G5-MIN($G$2:$G$7))/(MAX($G$2:$G$7)-MIN($G$2:$G$7)) -> 1 | H37: =(MAX($H$2:$H$7)-H5)/(MAX($H$2:$H$7)-MIN($H$2:$H$7)) -> 1 | I37: 4
D38: =(D6-MIN($D$2:$D$7))/(MAX($D$2:$D$7)-MIN($D$2:$D$7)) -> 0 | E38: =(E6-MIN($E$2:$E$7))/(MAX($E$2:$E$7)-MIN($E$2:$E$7)) -> 1 | F38: =(F6-MIN($F$2:$F$7))/(MAX($F$2:$F$7)-MIN($F$2:$F$7)) -> 0 | G38: =(G6-MIN($G$2:$G$7))/(MAX($G$2:$G$7)-MIN($G$2:$G$7)) -> 0.16666667 | H38: =(MAX($H$2:$H$7)-H6)/(MAX($H$2:$H$7)-MIN($H$2:$H$7)) -> 0.33333333 | I38: 5
D39: =(D7-MIN($D$2:$D$7))/(MAX($D$2:$D$7)-MIN($D$2:$D$7)) -> 0.5 | E39: =(E7-MIN($E$2:$E$7))/(MAX($E$2:$E$7)-MIN($E$2:$E$7)) -> 0.5 | F39: =(F7-MIN($F$2:$F$7))/(MAX($F$2:$F$7)-MIN($F$2:$F$7)) -> 1 | G39: =(G7-MIN($G$2:$G$7))/(MAX($G$2:$G$7)-MIN($G$2:$G$7)) -> 1 | H39: =(MAX($H$2:$H$7)-H7)/(MAX($H$2:$H$7)-MIN($H$2:$H$7)) -> 0.5 | I39: 6
D41: دسترسی به حمل و نقل عمومی | E41: تعداد بوستان در منطقه | F41: میزان ترافیک | G41: دسترسی به بازار خرید | H41: متوسط قیمت خرید | I41: منطقه
D42: =(D2-$D$48)/$D$49 -> 0.6761234 | E42: =(E2-$E$48)/$E$49 -> 0.77459667 | F42: =(F2-$F$48)/$F$49 -> -1.0945409 | G42: =(G2-$G$48)/$G$49 -> 0.29172998 | H42: =(H2-$H$48)/$H$49 -> -1.0245435 | I42: 1
D43: =(D3-$D$48)/$D$49 -> 1.6903085 | E43: =(E3-$E$48)/$E$49 -> -0.77459667 | F43: =(F3-$F$48)/$F$49 -> -0.4975186 | G43: =(G3-$G$48)/$G$49 -> -1.4586499 | H43: =(H3-$H$48)/$H$49 -> 0.86692145 | I43: 2
B44: توزیع نرمال | D44: =(D4-$D$48)/$D$49 -> -0.84515425 | E44: =(E4-$E$48)/$E$49 -> 0 | F44: =(F4-$F$48)/$F$49 -> 0.099503719 | G44: =(G4-$G$48)/$G$49 -> -0.14586499 | H44: =(H4-$H$48)/$H$49 -> 1.3397877 | I44: 3
D45: =(D5-$D$48)/$D$49 -> -0.3380617 | E45: =(E5-$E$48)/$E$49 -> -1.5491933 | F45: =(F5-$F$48)/$F$49 -> 1.2935483 | G45: =(G5-$G$48)/$G$49 -> 1.1669199 | H45: =(H5-$H$48)/$H$49 -> -1.4974098 | I45: 4
...

Sheet سوال3
A1: 40125003 | B1: D: | C1: 3 | N1: 5
F2: 1 | H2: گام اول: محاسبه درصد آرا و تعیین رتبه ها
H3: دسترسی به حمل و نقل عمومی | I3: تعداد بوستان در منطقه | J3: میزان ترافیک | K3: دسترسی به بازار | L3: متوسط قیمت | M3: شاخص
A4: گام اول: بی مقیاس سازی با روش نرم ساده | H4: =3*C1 -> 9 | I4: =2*C1 -> 6 | J4: =6*C1 -> 18 | K4: =4*C1 -> 12 | L4: 180 | M4: تعداد رای
A5: =سوال2!D17 -> دسترسی به حمل و نقل عمومی | B5: =سوال2!E17 -> تعداد بوستان در منطقه | C5: =سوال2!F17 -> میزان ترافیک | D5: =سوال2!G17 -> دسترسی به بازار خرید | E5: =سوال2!H17 -> متوسط قیمت خرید | F5: =سوال2!I17 -> منطقه | H5: =H4/SUM($H$4:$L$4) -> 0.04 | I5: =I4/SUM($H$4:$L$4) -> 0.026666667 | J5: =J4/SUM($H$4:$L$4) -> 0.08 | K5: =K4/SUM($H$4:$L$4) -> 0.053333333 | L5: =L4/SUM($H$4:$L$4) -> 0.8 | M5: درصد آرا
A6: =سوال2!D18 -> 0.20588235 | B6: =سوال2!E18 -> 0.20833333 | C6: =سوال2!F18 -> 0.10344828 | D6: =سوال2!G18 -> 0.18421053 | E6: =سوال2!H18 -> 0.22144112 | F6: =سوال2!I18 -> 1 | H6: =_xlfn.RANK.EQ(H5,$H$5:$L$5) -> 4 | I6: =_xlfn.RANK.EQ(I5,$H$5:$L$5) -> 5 | J6: =_xlfn.RANK.EQ(J5,$H$5:$L$5) -> 2 | K6: =_xlfn.RANK.EQ(K5,$H$5:$L$5) -> 3 | L6: =_xlfn.RANK.EQ(L5,$H$5:$L$5) -> 1 | M6: رتبه
A7: =سوال2!D19 -> 0.26470588 | B7: =سوال2!E19 -> 0.125 | C7: =سوال2!F19 -> 0.13793103 | D7: =سوال2!G19 -> 0.078947368 | E7: =سوال2!H19 -> 0.11072056 | F7: =سوال2!I19 -> 2
A8: =سوال2!D20 -> 0.11764706 | B8: =سوال2!E20 -> 0.16666667 | C8: =سوال2!F20 -> 0.17241379 | D8: =سوال2!G20 -> 0.15789474 | E8: =سوال2!H20 -> 0.098418278 | F8: =سوال2!I20 -> 3 | H8: گام دوم: تشکیل جدول جدید
A9: =سوال2!D21 -> 0.14705882 | B9: =سوال2!E21 -> 0.083333333 | C9: =سوال2!F21 -> 0.24137931 | D9: =سوال2!G21 -> 0.23684211 | E9: =سوال2!H21 -> 0.29525483 | F9: =سوال2!I21 -> 4 | H9: رتبه | I9: 1 | J9: 2 | K9: 3 | L9: 4 | M9: 5
A10: =سوال2!D22 -> 0.088235294 | B10: =سوال2!E22 -> 0.25 | C10: =سوال2!F22 -> 0.10344828 | D10: =سوال2!G22 -> 0.10526316 | E10: =سوال2!H22 -> 0.12653779 | F10: =سوال2!I22 -> 5 | H10: شاخص | I10: =L3 -> متوسط قیمت | J10: =J3 -> میزان ترافیک | K10: =K3 -> دسترسی به بازار | L10: =H3 -> دسترسی به حمل و نقل عمومی | M10: =I3 -> تعداد بوستان در منطقه
A11: =سوال2!D23 -> 0.17647059 | B11: =سوال2!E23 -> 0.16666667 | C11: =سوال2!F23 -> 0.24137931 | D11: =سوال2!G23 -> 0.23684211 | E11: =سوال2!H23 -> 0.14762742 | F11: =سوال2!I23 -> 6 | H11: درصد آرا | I11: =L5 -> 0.8 | J11: =J5 -> 0.08 | K11: =K5 -> 0.053333333 | L11: =H5 -> 0.04 | M11: =I5 -> 0.026666667
B13: K: | C13: =1/LN(6) -> 0.55811063 | D13: گام دوم: محاسبه عدد ثابت k | H13: گام سوم، چهارم، پنجم و ششم
H14: =H10 -> شاخص | I14: =I10 -> متوسط قیمت | J14: =J10 -> میزان ترافیک | K14: =K10 -> دسترسی به بازار | L14: =L10 -> دسترسی به حمل و نقل عمومی | M14: =M10 -> تعداد بوستان در منطقه
A15: گام سوم: محاسبه آنتروپی داده های نرمال شده برای هر معیار | H15: Sj | J15: =I11-J11 -> 0.72 | K15: =J11-K11 -> 0.026666667 | L15: =K11-L11 -> 0.013333333 | M15: =L11-M11 -> 0.013333333
A16: دسترسی به حمل و نقل عمومی | B16: تعداد بوستان در منطقه | C16: میزان ترافیک | D16: دسترسی به بازار خرید | E16: متوسط قیمت خرید | H16: Kj=Sj+1 | I16: =I15+1 -> 1 | J16: =J15+1 -> 1.72 | K16: =K15+1 -> 1.0266667 | L16: =L15+1 -> 1.0133333 | M16: =M15+1 -> 1.0133333
A17: =-$C$13*SUMPRODUCT(A6:A11,LN(A6:A11)) -> 0.96620612 | B17: =-$C$13*SUMPRODUCT(B6:B11,LN(B6:B11)) -> 0.96978836 | C17: =-$C$13*SUMPRODUCT(C6:C11,LN(C6:C11)) -> 0.96658595 | D17: =-$C$13*SUMPRODUCT(D6:D11,LN(D6:D11)) -> 0.96149668 | E17: =-$C$13*SUMPRODUCT(E6:E11,LN(E6:E11)) -> 0.95430516 | F17: Ej | H17: Qj(Q1=1,Qj=(QJ-1)/Kj | I17: 1 | J17: =I17/J16 -> 0.58139535 | K17: =J17/K16 -> 0.56629417 | L17: =K17/L16 -> 0.55884293 | M17: =L17/M16 -> 0.55148974
A18: =1-A17 -> 0.033793878 | B18: =1-B17 -> 0.03021164 | C18: =1-C17 -> 0.033414052 | D18: =1-D17 -> 0.038503323 | E18: =1-E17 -> 0.045694836 | F18: dj | H18: Wj | I18: =I17/SUM($I$17:$M$17) -> 0.30693468 | J18: =J17/SUM($I$17:$M$17) -> 0.1784504 | K18: =K17/SUM($I$17:$M$17) -> 0.17381532 | L18: =L17/SUM($I$17:$M$17) -> 0.17152828 | M18: =M17/SUM($I$17:$M$17) -> 0.16927133
A20: گام چهارم: محاسبه وزن هر معیار
A21: دسترسی به حمل و نقل عمومی | B21: تعداد بوستان در منطقه | C21: میزان ترافیک | D21: دسترسی به بازار خرید | E21: متوسط قیمت خرید | U21: 3 | AJ21: 4
A22: =A18/SUM($A$18:$E$18) -> 0.18607147 | B22: =B18/SUM($A$18:$E$18) -> 0.16634742 | C22: =C18/SUM($A$18:$E$18) -> 0.18398012 | D22: =D18/SUM($A$18:$E$18) -> 0.212002 | E22: =E18/SUM($A$18:$E$18) -> 0.25159898 | F22: w | H22: بی مقیاس سازی با روش نرم ساده | O22: transpose of ( بی مقیاس سازی با روش نرم ساده) | W22: بی مقیاس سازی با روش فاصله ای(فازی) | AD22: transpose of ( بی مقیاس سازی با روش فاصله ای)
H23: =سوال2!D17 -> دسترسی به حمل و نقل عمومی | I23: =سوال2!E17 -> تعداد بوستان در منطقه | J23: =سوال2!F17 -> میزان ترافیک | K23: =سوال2!G17 -> دسترسی به بازار خرید | L23: =سوال2!H17 -> متوسط قیمت خرید | M23: =سوال2!I17 -> منطقه | O23: {=TRANSPOSE(H24:L29)} -> 0.20588235 | P23: 0.26470588 | Q23: 0.11764706 | R23: 0.14705882 | S23: 0.088235294 | T23: 0.17647059 | W23: =سوال2!D33 -> دسترسی به حمل و نقل عمومی | X23: =سوال2!E33 -> تعداد بوستان در منطقه | Y23: =سوال2!F33 -> میزان ترافیک | Z23: =سوال2!G33 -> دسترسی به بازار خرید | AA23: =سوال2!H33 -> متوسط قیمت خرید | AB23: =سوال2!I33 -> منطقه | AD23: {=TRANSPOSE(W24:AA29)} -> 0.66666667 | AE23: 1 | AF23: 0.16666667 | AG23: 0.33333333 | AH23: 0 | AI23: 0.5
H24: =سوال2!D18 -> 0.20588235 | I24: =سوال2!E18 -> 0.20833333 | J24: =سوال2!F18 -> 0.10344828 | K24: =سوال2!G18 -> 0.18421053 | L24: =سوال2!H18 -> 0.22144112 | M24: =سوال2!I18 -> 1 | O24: 0.20833333 | P24: 0.125 | Q24: 0.16666667 | R24: 0.083333333 | S24: 0.25 | T24: 0.16666667 | W24: =سوال2!D34 -> 0.66666667 | X24: =سوال2!E34 -> 0.75 | Y24: =سوال2!F34 -> 0 | Z24: =سوال2!G34 -> 0.66666667 | AA24: =سوال2!H34 -> 0.83333333 | AB24: =سوال2!I34 -> 1 | AD24: 0.75 | AE24: 0.25 | AF24: 0.5 | AG24: 0 | AH24: 1 | AI24: 0.5
F25: 2 | H25: =سوال2!D19 -> 0.26470588 | I25: =سوال2!E19 -> 0.125 | J25: =سوال2!F19 -> 0.13793103 | K25: =سوال2!G19 -> 0.078947368 | L25: =سوال2!H19 -> 0.11072056 | M25: =سوال2!I19 -> 2 | O25: 0.10344828 | P25: 0.13793103 | Q25: 0.17241379 | R25: 0.24137931 | S25: 0.10344828 | T25: 0.24137931 | W25: =سوال2!D35 -> 1 | X25: =سوال2!E35 -> 0.25 | Y25: =سوال2!F35 -> 0.25 | Z25: =سوال2!G35 -> 0 | AA25: =سوال2!H35 -> 0.16666667 | AB25: =سوال2!I35 -> 2 | AD25: 0 | AE25: 0.25 | AF25: 0.5 | AG25: 1 | AH25: 0 | AI25: 1
A26: گام چهارم: محاسبه وزن هر معیار | H26: =سوال2!D20 -> 0.11764706 | I26: =سوال2!E20 -> 0.16666667 | J26: =سوال2!F20 -> 0.17241379 | K26: =سوال2!G20 -> 0.15789474 | L26: =سوال2!H20 -> 0.098418278 | M26: =سوال2!I20 -> 3 | O26: 0.18421053 | P26: 0.078947368 | Q26: 0.15789474 | R26: 0.23684211 | S26: 0.10526316 | T26: 0.23684211 | W26: =سوال2!D36 -> 0.16666667 | X26: =سوال2!E36 -> 0.5 | Y26: =سوال2!F36 -> 0.5 | Z26: =سوال2!G36 -> 0.5 | AA26: =سوال2!H36 -> 0 | AB26: =سوال2!I36 -> 3 | AD26: 0.66666667 | AE26: 0 | AF26: 0.5 | AG26: 1 | AH26: 0.16666667 | AI26: 1
A27: دسترسی به حمل و نقل عمومی | B27: تعداد بوستان در منطقه | C27: میزان ترافیک | D27: دسترسی به بازار خرید | E27: متوسط قیمت خرید | H27: =سوال2!D21 -> 0.14705882 | I27: =سوال2!E21 -> 0.083333333 | J27: =سوال2!F21 -> 0.24137931 | K27: =سوال2!G21 -> 0.23684211 | L27: =سوال2!H21 -> 0.29525483 | M27: =سوال2!I21 -> 4 | O27: 0.22144112 | P27: 0.11072056 | Q27: 0.098418278 | R27: 0.29525483 | S27: 0.12653779 | T27: 0.14762742 | W27: =سوال2!D37 -> 0.33333333 | X27: =سوال2!E37 -> 0 | Y27: =سوال2!F37 -> 1 | Z27: =سوال2!G37 -> 1 | AA27: =سوال2!H37 -> 1 | AB27: =سوال2!I37 -> 4 | AD27: 0.83333333 | AE27: 0.16666667 | AF27: 0 | AG27: 1 | AH27: 0.33333333 | AI27: 0.5
A28: 0.15 | B28: 0.05 | C28: 0.2 | D28: 0.1 | E28: 0.5 | F28: lambda | H28: =سوال2!D22 -> 0.088235294 | I28: =سوال2!E22 -> 0.25 | J28: =سوال2!F22 -> 0.10344828 | K28: =سوال2!G22 -> 0.10526316 | L28: =سوال2!H22 -> 0.12653779 | M28: =سوال2!I22 -> 5 | O28: #N/A | P28: #N/A | Q28: #N/A | R28: #N/A | S28: #N/A | T28: #N/A | W28: =سوال2!D38 -> 0 | X28: =سوال2!E38 -> 1 | Y28: =سوال2!F38 -> 0 | Z28: =سوال2!G38 -> 0.16666667 | AA28: =سوال2!H38 -> 0.33333333 | AB28: =سوال2!I38 -> 5
A29: =A22 -> 0.18607147 | B29: =B22 -> 0.16634742 | C29: =C22 -> 0.18398012 | D29: =D22 -> 0.212002 | E29: =E22 -> 0.25159898 | F29: w | H29: =سوال2!D23 -> 0.17647059 | I29: =سوال2!E23 -> 0.16666667 | J29: =سوال2!F23 -> 0.24137931 | K29: =سوال2!G23 -> 0.23684211 | L29: =سوال2!H23 -> 0.14762742 | M29: =سوال2!I23 -> 6 | W29: =سوال2!D39 -> 0.5 | X29: =سوال2!E39 -> 0.5 | Y29: =سوال2!F39 -> 1 | Z29: =سوال2!G39 -> 1 | AA29: =سوال2!H39 -> 0.5 | AB29: =سوال2!I39 -> 6
A30: =(A28*A29)/SUMPRODUCT($A$28:$E$28,$A$29:$E$29) -> 0.12685319 | B30: =(B28*B29)/SUMPRODUCT($A$28:$E$28,$A$29:$E$29) -> 0.037802141 | C30: =(C28*C29)/SUMPRODUCT($A$28:$E$28,$A$29:$E$29) -> 0.16723656 | D30: =(D28*D29)/SUMPRODUCT($A$28:$E$28,$A$29:$E$29) -> 0.09635412 | E30: =(E28*E29)/SUMPRODUCT($A$28:$E$28,$A$29:$E$29) -> 0.571754 | F30: w prime
F32: 6
H33: w1 | I33: 0.52858011 | J33: M | K33: =MAX(I38:I43) -> 0.29744271 | W33: w1 | X33: 0.16854286 | Y33: M | Z33: =MAX(X38:X43) -> 0.54605238
A34: =A5 -> دسترسی به حمل و نقل عمومی | B34: =B5 -> تعداد بوستان در منطقه | C34: =C5 -> میزان ترافیک | D34: =D5 -> دسترسی به بازار خرید | E34: =E5 -> متوسط قیمت خرید | H34: w2 | I34: 1.4966339 | J34: e | K34: 0.001 | W34: w2 | X34: 0.45344762 | Y34: e | Z34: 0.001
A35: =A22 -> 0.18607147 | B35: =B22 -> 0.16634742 | C35: =C22 -> 0.18398012 | D35: =D22 -> 0.212002 | E35: =E22 -> 0.25159898 | F35: آنتروپی بدون تعدیل وزن | H35: w3 | I35: 2.7214333 | W35: w3 | X35: 0.68750476
A36: =A30 -> 0.12685319 | B36: =B30 -> 0.037802141 | C36: =C30 -> 0.16723656 | D36: =D30 -> 0.09635412 | E36: =E30 -> 0.571754 | F36: آنتروپی با تعدیل وزن | H36: w4 | I36: 0.001 | W36: w4 | X36: 0.001
A37: {=TRANSPOSE(I33:I37)} -> 0.52858011 | B37: 1.4966339 | C37: 2.7214333 | D37: 0.001 | E37: 0.001 | F37: تحلیل پوششی با نرم ساده | H37: w5 | I37: 0.001 | W37: w5 | X37: 0.001
A38: {=TRANSPOSE(X33:X37)} -> 0.16854286 | B38: 0.45344762 | C38: 0.68750476 | D38: 0.001 | E38: 0.001 | F38: تحلیل پوششی با روش فاصله ای | H38: d1 | I38: 0.29744271 | W38: d1 | X38: 0.54605238
A39: =L18 -> 0.17152828 | B39: =M18 -> 0.16927133 | C39: =J18 -> 0.1784504 | D39: =L18 -> 0.17152828 | E39: =I18 -> 0.30693468 | F39: روش SWARA | H39: d2 | I39: 0.29744271 | W39: d2 | X39: 0.54605238
H40: d3 | I40: 0.21890616 | W40: d3 | X40: 0.40093333
H41: d4 | I41: 0.14011834 | W41: d4 | X41: 0.25431429
H42: d5 | I42: 0.29744271 | W42: d5 | X42: 0.54605238
H43: d6 | I43: 0 | W43: d6 | X43: 0
...
