Workbook
Name PCM: 'Q1'!$A$8:$E$12

Sheet Q1
A1: X | B1: =_xlfn.CEILING.MATH(AVERAGE(4,0,1,2,5,0,2,0)) -> 2
A3: Y | B3: =_xlfn.CEILING.MATH(AVERAGE(0,2,0)) -> 1
H6: A1 | I6: {=B9:E12} -> 1 | J6: 0.5 | K6: 1.5 | L6: 1 | N6: w1 | O6: =SUM(I6:L6)/SUM($I$6:$L$9) -> 0.21052632 | Q6: Wt | R6: {=TRANSPOSE(O51:O54)} -> 0.21631481 | S6: 0.31050013 | T6: 0.13063993 | U6: 0.34254513
I7: 2 | J7: 1 | K7: 3 | L7: 0.5 | N7: w2 | O7: =SUM(I7:L7)/SUM($I$6:$L$9) -> 0.34210526
A8: PCM | B8: معیار اول | C8: معیار دوم | D8: معیار سوم | E8: معیار چهارم | I8: 0.66666667 | J8: 0.33333333 | K8: 1 | L8: 0.5 | N8: w3 | O8: =SUM(I8:L8)/SUM($I$6:$L$9) -> 0.13157895 | R8: l1max | S8: =SUMPRODUCT(B9:E9,_xlfn.ANCHORARRAY($R$6))/R6 -> #NAME?
A9: معیار اول | B9: 1 | C9: =1/B1 -> 0.5 | D9: =(3/2)*B3 -> 1.5 | E9: 1 | I9: 1 | J9: 2 | K9: 2 | L9: 1 | N9: w4 | O9: =SUM(I9:L9)/SUM($I$6:$L$9) -> 0.31578947 | R9: l2max | S9: =SUMPRODUCT(B10:E10,_xlfn.ANCHORARRAY($R$6))/S6 -> #NAME?
A10: معیار دوم | B10: =1/C9 -> 2 | C10: 1 | D10: =(3/2)*B1 -> 3 | E10: =(1/2)*B3 -> 0.5 | R10: l3max | S10: =SUMPRODUCT(B11:E11,_xlfn.ANCHORARRAY($R$6))/T6 -> #NAME?
A11: معیار سوم | B11: =1/D9 -> 0.66666667 | C11: =1/D10 -> 0.33333333 | D11: 1 | E11: =1/B1 -> 0.5 | H11: A2 | I11: {=MMULT(B9:E12,$B$9:$E$12)} -> 4 | J11: 3.5 | K11: 6.5 | L11: 3 | N11: w1 | O11: =SUM(I11:L11)/SUM($I$11:$L$14) -> 0.21161826 | R11: l4max | S11: =SUMPRODUCT(B12:E12,_xlfn.ANCHORARRAY($R$6))/U6 -> #NAME?
A12: معیار چهارم | B12: =1/E9 -> 1 | C12: =1/E10 -> 2 | D12: =1/E11 -> 2 | E12: 1 | I12: 6.5 | J12: 4 | K12: 10 | L12: 4.5 | N12: w2 | O12: =SUM(I12:L12)/SUM($I$11:$L$14) -> 0.31120332 | R12: lmax | S12: =SUM(S8:S11)/4 -> #NAME?
I13: 2.5 | J13: 2 | K13: 4 | L13: 1.8333333 | N13: w3 | O13: =SUM(I13:L13)/SUM($I$11:$L$14) -> 0.12863071
I14: 7.3333333 | J14: 5.1666667 | K14: 11.5 | L14: 4 | N14: w4 | O14: =SUM(I14:L14)/SUM($I$11:$L$14) -> 0.34854772 | R14: C.I | S14: =(S12-4)/(4-1) -> #NAME?
R15: R.I | S15: 0.9
H16: A3 | I16: {=MMULT(I11:L14,$B$9:$E$12)} -> 18.333333 | J16: 13.666667 | K16: 29 | L16: 12 | N16: w1 | O16: =SUM(I16:L16)/SUM($I$16:$L$19) -> 0.21683168 | R16: C.R | S16: =S14/S15 -> #NAME?
I17: 25.666667 | J17: 19.583333 | K17: 40.75 | L17: 18 | N17: w2 | O17: =SUM(I17:L17)/SUM($I$16:$L$19) -> 0.30891089
I18: 11 | J18: 8.25 | K18: 17.416667 | L18: 7.3333333 | N18: w3 | O18: =SUM(I18:L18)/SUM($I$16:$L$19) -> 0.13069307
I19: 29.333333 | J19: 20.666667 | K19: 46 | L19: 19.666667 | N19: w4 | O19: =SUM(I19:L19)/SUM($I$16:$L$19) -> 0.34356436
H21: A4 | I21: {=MMULT(I16:L19,$B$9:$E$12)} -> 77 | J21: 56.5 | K21: 121.5 | L21: 51.666667 | N21: w1 | O21: =SUM(I21:L21)/SUM($I$21:$L$24) -> 0.21652153
I22: 110 | J22: 82 | K22: 174 | L22: 73.833333 | N22: w2 | O22: =SUM(I22:L22)/SUM($I$21:$L$24) -> 0.31054366
I23: 46.444444 | J23: 34.222222 | K23: 73.333333 | L23: 31.166667 | N23: w3 | O23: =SUM(I23:L23)/SUM($I$21:$L$24) -> 0.13073664
I24: 121 | J24: 90 | K24: 191.33333 | L24: 82.333333 | N24: w4 | O24: =SUM(I24:L24)/SUM($I$21:$L$24) -> 0.34219816
H26: A5 | I26: {=MMULT(I21:L24,$B$9:$E$12)} -> 322.66667 | J26: 238.83333 | K26: 509.83333 | L26: 217.66667 | N26: w1 | O26: =SUM(I26:L26)/SUM($I$26:$L$29) -> 0.2162792
I27: 463.83333 | J27: 342.66667 | K27: 732.66667 | L27: 311.83333 | N27: w2 | O27: =SUM(I27:L27)/SUM($I$26:$L$29) -> 0.31057626
I28: 194.94444 | J28: 144.22222 | K28: 308 | L28: 131.38889 | N28: w3 | O28: =SUM(I28:L28)/SUM($I$26:$L$29) -> 0.13063256
I29: 510.88889 | J29: 378.94444 | K29: 807.5 | L29: 344 | N29: w4 | O29: =SUM(I29:L29)/SUM($I$26:$L$29) -> 0.34251198
H31: A6 | I31: {=MMULT(I26:L29,$B$9:$E$12)} -> 1357.8889 | J31: 1005.4444 | K31: 2145.6667 | L31: 914.66667 | N31: w1 | O31: =SUM(I31:L31)/SUM($I$31:$L$34) -> 0.2163064
I32: 1949.4444 | J32: 1442.4722 | K32: 3080.0833 | L32: 1313.3333 | N32: w2 | O32: =SUM(I32:L32)/SUM($I$31:$L$34) -> 0.31049427
I33: 820.11111 | J33: 607.13889 | K33: 1295.8611 | L33: 552.44444 | N33: w3 | O33: =SUM(I33:L33)/SUM($I$31:$L$34) -> 0.13063554
I34: 2151.1111 | J34: 1591.5556 | K34: 3398.6667 | L34: 1448.1111 | N34: w4 | O34: =SUM(I34:L34)/SUM($I$31:$L$34) -> 0.34256379
H36: A7 | I36: {=MMULT(I31:L34,$B$9:$E$12)} -> 5713.8889 | J36: 4228.9444 | K36: 9028.1667 | L36: 3848.1111 | N36: w1 | O36: =SUM(I36:L36)/SUM($I$36:$L$39) -> 0.21631699
I37: 8201.1111 | J37: 6070.5556 | K37: 12958.333 | L37: 5524.0556 | N37: w2 | O37: =SUM(I37:L37)/SUM($I$36:$L$39) -> 0.3104967
I38: 3450.7407 | J38: 2554.037 | K38: 5452.3333 | L38: 2324.0556 | N38: w3 | O38: =SUM(I38:L38)/SUM($I$36:$L$39) -> 0.13064052
I39: 9048.1111 | J39: 6696.2222 | K39: 14296.222 | L39: 6094.3333 | N39: w4 | O39: =SUM(I39:L39)/SUM($I$36:$L$39) -> 0.34254579
H41: A8 | I41: {=MMULT(I36:L39,$B$9:$E$12)} -> 24038.667 | J41: 17791.5 | K41: 37982.056 | L41: 16190.556 | N41: w1 | O41: =SUM(I41:L41)/SUM($I$41:$L$44) -> 0.21631513
I42: 34505.167 | J42: 25538.667 | K42: 54519.778 | L42: 23239.611 | N42: w2 | O42: =SUM(I42:L42)/SUM($I$41:$L$44) -> 0.31050062
I43: 14517.759 | J43: 10744.963 | K43: 22938.667 | L43: 9777.9815 | N43: w3 | O43: =SUM(I43:L43)/SUM($I$41:$L$44) -> 0.13064013
I44: 38065.704 | J44: 28174.352 | K44: 60145.722 | L44: 25638.667 | N44: w4 | O44: =SUM(I44:L44)/SUM($I$41:$L$44) -> 0.34254412
H46: A9 | I46: {=MMULT(I41:L44,$B$9:$E$12)} -> 101133.59 | J46: 74852.63 | K46: 159795.67 | L46: 68116 | N46: w1 | O46: =SUM(I46:L46)/SUM($I$46:$L$49) -> 0.2163147
I47: 145168.63 | J47: 107443.73 | K47: 229372.75 | L47: 97774 | N47: w2 | O47: =SUM(I47:L47)/SUM($I$46:$L$49) -> 0.31050031
I48: 61078.111 | J48: 45206.028 | K48: 96506.157 | L48: 41137.556 | N48: w3 | O48: =SUM(I48:L48)/SUM($I$46:$L$49) -> 0.1306399
I49: 160150.22 | J49: 118533.11 | K49: 253044.67 | L49: 107864.41 | N49: w4 | O49: =SUM(I49:L49)/SUM($I$46:$L$49) -> 0.34254509
...

Sheet Q2
A1: X | B1: =_xlfn.CEILING.MATH(AVERAGE(4,0,1,2,5,0,2,0)) -> 2
A3: Y | B3: =_xlfn.CEILING.MATH(AVERAGE(0,2,0)) -> 1 | H3: روش مجموع سطری | P3: روش بردار ویژه | Q3: روش مجموع سطری | R3: روش مجموع ستونی | S3: روش میانگین حسابی | T3: روش میانگین هندسی
H4: w1 | I4: =SUM('Q1'!$B9:$E9)/SUM('Q1'!$B$9:$E$12) -> 0.21052632 | O4: w1 | P4: {='Q1'!O51:O54} -> 0.21631481 | Q4: {=I4:I7} -> 0.21052632 | R4: {=I10:I13} -> 0.24561404 | S4: {=M17:M20} -> 0.21951346 | T4: {=I23:I26} -> 0.24154154
H5: w2 | I5: =SUM('Q1'!$B10:$E10)/SUM('Q1'!$B$9:$E$12) -> 0.34210526 | O5: w2 | P5: 0.31050013 | Q5: 0.34210526 | R5: 0.20175439 | S5: 0.31402692 | T5: 0.34159132
H6: w3 | I6: =SUM('Q1'!$B11:$E11)/SUM('Q1'!$B$9:$E$12) -> 0.13157895 | O6: w3 | P6: 0.13063993 | Q6: 0.13157895 | R6: 0.39473684 | S6: 0.13245342 | T6: 0.14985315
H7: w4 | I7: =SUM('Q1'!$B12:$E12)/SUM('Q1'!$B$9:$E$12) -> 0.31578947 | O7: w4 | P7: 0.34254513 | Q7: 0.31578947 | R7: 0.15789474 | S7: 0.33400621 | T7: 0.36706376
A8: {=PCM} -> PCM | B8: معیار اول | C8: معیار دوم | D8: معیار سوم | E8: معیار چهارم
A9: معیار اول | B9: 1 | C9: 0.5 | D9: 1.5 | E9: 1 | H9: روش مجموع ستونی | O9: اختلاف با روش بردار ویژه
A10: معیار دوم | B10: 2 | C10: 1 | D10: 3 | E10: 0.5 | H10: w1 | I10: =SUM('Q1'!B$9:B$12)/SUM('Q1'!$B$9:$E$12) -> 0.24561404 | P10: روش مجموع سطری | Q10: روش مجموع ستونی | R10: روش میانگین حسابی | S10: روش میانگین هندسی
A11: معیار سوم | B11: 0.66666667 | C11: 0.33333333 | D11: 1 | E11: 0.5 | H11: w2 | I11: =SUM('Q1'!C$9:C$12)/SUM('Q1'!$B$9:$E$12) -> 0.20175439 | O11: w1 | P11: =ABS($P$4-Q4) -> 0.0057884971 | Q11: =ABS($P$4-R4) -> 0.029299222 | R11: =ABS($P$4-S4) -> 0.0031986447 | S11: =ABS($P$4-T4) -> 0.025226728
A12: معیار چهارم | B12: 1 | C12: 2 | D12: 2 | E12: 1 | H12: w3 | I12: =SUM('Q1'!D$9:D$12)/SUM('Q1'!$B$9:$E$12) -> 0.39473684 | O12: w2 | P12: =ABS($P$5-Q5) -> 0.031605134 | Q12: =ABS($P$5-R5) -> 0.10874574 | R12: =ABS($P$5-S5) -> 0.0035267862 | S12: =ABS($P$5-T5) -> 0.031091194
H13: w4 | I13: =SUM('Q1'!E$9:E$12)/SUM('Q1'!$B$9:$E$12) -> 0.15789474 | O13: w3 | P13: =ABS($P$6-Q6) -> 0.0009390162 | Q13: =ABS($P$6-R6) -> 0.26409691 | R13: =ABS($P$6-S6) -> 0.001813485 | S13: =ABS($P$6-T6) -> 0.019213223
O14: w4 | P14: =ABS($P$7-Q7) -> 0.026755653 | Q14: =ABS($P$7-R7) -> 0.18465039 | R14: =ABS($P$7-S7) -> 0.0085389158 | S14: =ABS($P$7-T7) -> 0.024518637
H15: روش میانگین حسابی | O15: مجموع خطا | P15: =SUM(P11:P14) -> 0.065088301 | Q15: =SUM(Q11:Q14) -> 0.58679227 | R15: =SUM(R11:R14) -> 0.017077832 | S15: =SUM(S11:S14) -> 0.10004978
H16: ماتریس نرمال شده با روش نرم ساده
H17: ='Q1'!B9/SUM('Q1'!B$9:B$12) -> 0.21428571 | I17: ='Q1'!C9/SUM('Q1'!C$9:C$12) -> 0.13043478 | J17: ='Q1'!D9/SUM('Q1'!D$9:D$12) -> 0.2 | K17: ='Q1'!E9/SUM('Q1'!E$9:E$12) -> 0.33333333 | L17: w1 | M17: =AVERAGE($H17:$K17) -> 0.21951346 | O17: با در نظر گرفتن میزان خطا، روش میانگین حسابی نسبت به سایر روش‌ها به بردار ویژه نزدیک‌تر است، اما در بیشتر موارد، روش میانگین هندسی دقیق‌ترین تقریب را به روش بردار ویژه ارائه می‌دهد.
H18: ='Q1'!B10/SUM('Q1'!B$9:B$12) -> 0.42857143 | I18: ='Q1'!C10/SUM('Q1'!C$9:C$12) -> 0.26086957 | J18: ='Q1'!D10/SUM('Q1'!D$9:D$12) -> 0.4 | K18: ='Q1'!E10/SUM('Q1'!E$9:E$12) -> 0.16666667 | L18: w2 | M18: =AVERAGE($H18:$K18) -> 0.31402692
H19: ='Q1'!B11/SUM('Q1'!B$9:B$12) -> 0.14285714 | I19: ='Q1'!C11/SUM('Q1'!C$9:C$12) -> 0.086956522 | J19: ='Q1'!D11/SUM('Q1'!D$9:D$12) -> 0.13333333 | K19: ='Q1'!E11/SUM('Q1'!E$9:E$12) -> 0.16666667 | L19: w3 | M19: =AVERAGE($H19:$K19) -> 0.13245342
H20: ='Q1'!B12/SUM('Q1'!B$9:B$12) -> 0.21428571 | I20: ='Q1'!C12/SUM('Q1'!C$9:C$12) -> 0.52173913 | J20: ='Q1'!D12/SUM('Q1'!D$9:D$12) -> 0.26666667 | K20: ='Q1'!E12/SUM('Q1'!E$9:E$12) -> 0.33333333 | L20: w4 | M20: =AVERAGE($H20:$K20) -> 0.33400621
H22: روش میانگین هندسی
H23: w1 | I23: =GEOMEAN('Q1'!$B9:$E9)/SUM(GEOMEAN('Q1'!$B$9:$E$9),GEOMEAN('Q1'!$B$9:$E$9),GEOMEAN('Q1'!$B$11:$E$11),GEOMEAN('Q1'!$B$12:$E$12)) -> 0.24154154
H24: w2 | I24: =GEOMEAN('Q1'!$B10:$E10)/SUM(GEOMEAN('Q1'!$B$9:$E$9),GEOMEAN('Q1'!$B$9:$E$9),GEOMEAN('Q1'!$B$11:$E$11),GEOMEAN('Q1'!$B$12:$E$12)) -> 0.34159132
H25: w3 | I25: =GEOMEAN('Q1'!$B11:$E11)/SUM(GEOMEAN('Q1'!$B$9:$E$9),GEOMEAN('Q1'!$B$9:$E$9),GEOMEAN('Q1'!$B$11:$E$11),GEOMEAN('Q1'!$B$12:$E$12)) -> 0.14985315
H26: w4 | I26: =GEOMEAN('Q1'!$B12:$E12)/SUM(GEOMEAN('Q1'!$B$9:$E$9),GEOMEAN('Q1'!$B$9:$E$9),GEOMEAN('Q1'!$B$11:$E$11),GEOMEAN('Q1'!$B$12:$E$12)) -> 0.36706376

Sheet Q3
A1: X | B1: =_xlfn.CEILING.MATH(AVERAGE(4,0,1,2,5,0,2,0)) -> 2
H2: تابع هدف
A3: Y | B3: =_xlfn.CEILING.MATH(AVERAGE(0,2,0)) -> 1 | K3: {=SUM(SUM(POWER(B9:E9*H10:K10-$H$10,2)), SUM(POWER(B10:E10*H10:K10-$I$10,2)), SUM(POWER(B11:E11*H10:K10-$J$10,2)), SUM(POWER(B12:E12*H10:K10-$K$10,2)))} -> 0.15060751
O4: Min ∑_(i=1)^4▒∑_(j=1)^4▒〖(u_ij.w_j-w_i)〗^2
A8: {=PCM} -> PCM | B8: معیار اول | C8: معیار دوم | D8: معیار سوم | E8: معیار چهارم | H8: متغیرها
A9: معیار اول | B9: 1 | C9: 0.5 | D9: 1.5 | E9: 1 | H9: w1 | I9: w2 | J9: w3 | K9: w4
A10: معیار دوم | B10: 2 | C10: 1 | D10: 3 | E10: 0.5 | H10: 0.22148601 | I10: 0.2802394 | J10: 0.13543652 | K10: 0.36283807
A11: معیار سوم | B11: 0.66666667 | C11: 0.33333333 | D11: 1 | E11: 0.5
A12: معیار چهارم | B12: 1 | C12: 2 | D12: 2 | E12: 1 | H12: محدودیت ها
H13: ∑wi = 1 | J13: =SUM(H10:K10) -> 1

Sheet Q4
A1: X | B1: =_xlfn.CEILING.MATH(AVERAGE(4,0,1,2,5,0,2,0)) -> 2
H2: ماتریس V | L2: ماتریس U
A3: Y | B3: =_xlfn.CEILING.MATH(AVERAGE(0,2,0)) -> 1 | H3: 0.33333333 | I3: 0 | J3: 0 | K3: 0.66666667 | L3: 1
H4: 0.5 | I4: 0 | J4: 0 | K4: 0 | L4: 1
H5: 0.33333333 | I5: 0 | J5: 0 | K5: 0.66666667 | L5: 1
H6: 0 | I6: 0.5 | J6: 0 | K6: 0 | L6: 1
A8: PCM | B8: معیار اول | C8: معیار دوم | D8: معیار سوم | E8: معیار چهارم | H8: مدل برای محاسبه وزن معیار اول | N8: مدل برای محاسبه وزن معیار دوم | T8: وزن‌های نرمال شده
A9: معیار اول | B9: 1 | C9: 0.5 | D9: 1.5 | E9: 1 | H9: تابع هدف | N9: تابع هدف | T9: w1 | U9: =L10/SUM(L10,R10,L21,R21) -> 0.28125
A10: معیار دوم | B10: 2 | C10: 1 | D10: 3 | E10: 0.5 | H10: Max Z = w1 | L10: =SUMPRODUCT(B9:E9,H3:K3) -> 1 | N10: Max Z = w2 | R10: =SUMPRODUCT(B10:E10,H4:K4) -> 1 | T10: w2 | U10: =R10/SUM(L10,R10,L21,R21) -> 0.28125
A11: معیار سوم | B11: 0.66666667 | C11: 0.33333333 | D11: 1 | E11: 0.5 | T11: w3 | U11: =L21/SUM(L10,R10,L21,R21) -> 0.15625
A12: معیار چهارم | B12: 1 | C12: 2 | D12: 2 | E12: 1 | H12: محدودیت ها | N12: محدودیت ها | T12: w4 | U12: =R21/SUM(L10,R10,L21,R21) -> 0.28125
H13: u11 = 1 | L13: =L3 -> 1 | N13: u22 = 1 | R13: =L4 -> 1
H14: V1T Y-u11 ≤ 0 | L14: =SUMPRODUCT(B9:E9,$H$3:$K$3)-$L$3 -> 0 | N14: V2T Y-u22 ≤ 0 | R14: =SUMPRODUCT(B9:E9,$H$4:$K$4)-$L$4 -> -0.5
L15: =SUMPRODUCT(B10:E10,$H$3:$K$3)-$L$3 -> 0 | R15: =SUMPRODUCT(B10:E10,$H$4:$K$4)-$L$4 -> 0
L16: =SUMPRODUCT(B11:E11,$H$3:$K$3)-$L$3 -> -0.44444444 | R16: =SUMPRODUCT(B11:E11,$H$4:$K$4)-$L$4 -> -0.66666667
L17: =SUMPRODUCT(B12:E12,$H$3:$K$3)-$L$3 -> 0 | R17: =SUMPRODUCT(B12:E12,$H$4:$K$4)-$L$4 -> -0.5
H19: مدل برای محاسبه وزن معیار سوم | N19: مدل برای محاسبه وزن معیار چهارم
H20: تابع هدف | N20: تابع هدف
H21: Max Z = w3 | L21: =SUMPRODUCT(B11:E11,H5:K5) -> 0.55555556 | N21: Max Z = w4 | R21: =SUMPRODUCT(B12:E12,H6:K6) -> 1
H23: محدودیت ها | N23: محدودیت ها
H24: u33 = 1 | L24: =L5 -> 1 | N24: u44 = 1 | R24: =L6 -> 1
H25: V3T Y-u33 ≤ 0 | L25: =SUMPRODUCT(B9:E9,$H$5:$K$5)-$L$5 -> 0 | N25: V4T Y-u44 ≤ 0 | R25: =SUMPRODUCT(B9:E9,$H$6:$K$6)-$L$6 -> -0.75
L26: =SUMPRODUCT(B10:E10,$H$5:$K$5)-$L$5 -> 0 | R26: =SUMPRODUCT(B10:E10,$H$6:$K$6)-$L$6 -> -0.5
L27: =SUMPRODUCT(B11:E11,$H$5:$K$5)-$L$5 -> -0.44444444 | R27: =SUMPRODUCT(B11:E11,$H$6:$K$6)-$L$6 -> -0.83333333
L28: =SUMPRODUCT(B12:E12,$H$5:$K$5)-$L$5 -> 0 | R28: =SUMPRODUCT(B12:E12,$H$6:$K$6)-$L$6 -> 0

Sheet Q5-1
A1: X | B1: =_xlfn.CEILING.MATH(AVERAGE(4,0,1,2,5,0,2,0)) -> 2
H2: تابع هدف
A3: Y | B3: =_xlfn.CEILING.MATH(AVERAGE(0,2,0)) -> 1 | H3: Min z = z12+z13+z14+z23+z24+z34 | K3: =ABS(LN(I11))+ABS(LN(J11))+ABS(LN(K11))+ABS(LN(J12))+ABS(LN(K12))+ABS(LN(K13)) -> 1.6739777
H4: متغیرها
H5: W
H6: w1 | J6: 1 | K6: =J6/SUM($J$6:$J$9) -> 0.24999993
H7: w2 | J7: 1.5000012 | K7: =J7/SUM($J$6:$J$9) -> 0.3750002
A8: {=PCM} -> PCM | B8: معیار اول | C8: معیار دوم | D8: معیار سوم | E8: معیار چهارم | H8: w3 | J8: 0.49999993 | K8: =J8/SUM($J$6:$J$9) -> 0.12499995
A9: معیار اول | B9: 1 | C9: 0.5 | D9: 1.5 | E9: 1 | H9: w4 | J9: 1 | K9: =J9/SUM($J$6:$J$9) -> 0.24999993
A10: معیار دوم | B10: 2 | C10: 1 | D10: 3 | E10: 0.5 | H10: ε
A11: معیار سوم | B11: 0.66666667 | C11: 0.33333333 | D11: 1 | E11: 0.5 | H11: 1 | I11: 1.3333322 | J11: 1.3333335 | K11: 1
A12: معیار چهارم | B12: 1 | C12: 2 | D12: 2 | E12: 1 | H12: 0.75000061 | I12: 1 | J12: 1.000001 | K12: 3.0000024
H13: 0.74999989 | I13: 0.99999905 | J13: 1 | K13: 0.99999986
H14: 1 | I14: 0.33333306 | J14: 1.0000001 | K14: 1
H15: محدودیت ها
H16: xi-xj-yij=ln(aij) | I16: =LN(J6)-LN(J7)-LN(I11)-LN(C9) -> 3.9662162e-11 | J16: zij ≥ yij | K16: =ABS(LN(I11))-LN(I11) -> 0
I17: =LN(J6)-LN(J8)-LN(J11)-LN(D9) -> 0 | K17: =ABS(LN(J11))-LN(J11) -> 0
I18: =LN(J6)-LN(J9)-LN(K11)-LN(E9) -> 0 | K18: =ABS(LN(K11))-LN(K11) -> 0
I19: =LN(J7)-LN(J6)-LN(H12)-LN(B10) -> -8.6054497e-12 | K19: =ABS(LN(J12))-LN(J12) -> 0
I20: =LN(J7)-LN(J8)-LN(J12)-LN(D10) -> -9.9189545e-12 | K20: =ABS(LN(K12))-LN(K12) -> 0
I21: =LN(J7)-LN(J9)-LN(K12)-LN(E10) -> 8.5109697e-13 | K21: =ABS(LN(K13))-LN(K13) -> 2.8114718e-07
I22: =LN(J8)-LN(J6)-LN(H13)-LN(B11) -> 0 | J22: zij ≥ yji | K22: =ABS(LN(I11))-LN(H12) -> 0.57536252
I23: =LN(J8)-LN(J7)-LN(I13)-LN(C11) -> 3.9352965e-11 | K23: =ABS(LN(J11))-LN(H13) -> 0.57536443
I24: =LN(J8)-LN(J9)-LN(K13)-LN(E11) -> 0 | K24: =ABS(LN(K11))-LN(H14) -> 0
I25: =LN(J9)-LN(J6)-LN(H14)-LN(B12) -> 0 | K25: =ABS(LN(J12))-LN(I13) -> 1.906907e-06
I26: =LN(J9)-LN(J7)-LN(I14)-LN(C12) -> 6.0675021e-11 | K26: =ABS(LN(K12))-LN(I14) -> 2.1972262
I27: =LN(J9)-LN(J8)-LN(J14)-LN(D12) -> 0 | K27: =ABS(LN(K13))-LN(J14) -> -1.1205833e-16
H28: x1 = 0 | I28: =LN(J6) -> 0 | J28: zij ≥ 0 | K28: =ABS(LN(I11)) -> 0.28768126
H29: xi-xj ≥ 0 | I29: =LN(J6)-LN(J8) -> 0.69314732 | K29: =ABS(LN(J11)) -> 0.28768221
I30: =LN(J7)-LN(J8) -> 1.0986132 | K30: =ABS(LN(K11)) -> 0
I31: =LN(J7)-LN(J9) -> 0.40546592 | K31: =ABS(LN(J12)) -> 9.534388e-07
K32: =ABS(LN(K12)) -> 1.0986131
K33: =ABS(LN(K13)) -> 1.4057359e-07

Sheet Q5-2
A1: X | B1: =_xlfn.CEILING.MATH(AVERAGE(4,0,1,2,5,0,2,0)) -> 2
H2: تابع هدف
A3: Y | B3: =_xlfn.CEILING.MATH(AVERAGE(0,2,0)) -> 1 | H3: z* | I3: 1.6739777 | J3: Min Zmax | K3: =H16 -> 0.69314676
H4: متغیرها
H5: W
H6: w1 | J6: 1 | K6: =J6/SUM($J$6:$J$9) -> 0.27272732
H7: w2 | J7: 0.99999981 | K7: =J7/SUM($J$6:$J$9) -> 0.27272727
A8: {=PCM} -> PCM | B8: معیار اول | C8: معیار دوم | D8: معیار سوم | E8: معیار چهارم | H8: w3 | J8: 0.66666623 | K8: =J8/SUM($J$6:$J$9) -> 0.18181809
A9: معیار اول | B9: 1 | C9: 0.5 | D9: 1.5 | E9: 1 | H9: w4 | J9: 1 | K9: =J9/SUM($J$6:$J$9) -> 0.27272732
A10: معیار دوم | B10: 2 | C10: 1 | D10: 3 | E10: 0.5 | H10: ε
A11: معیار سوم | B11: 0.66666667 | C11: 0.33333333 | D11: 1 | E11: 0.5 | H11: 1 | I11: 2 | J11: 1.0000007 | K11: 1
A12: معیار چهارم | B12: 1 | C12: 2 | D12: 2 | E12: 1 | H12: 0.4999999 | I12: 1 | J12: 0.50000023 | K12: 1.9999996
H13: 0.99999934 | I13: 2.0000003 | J13: 1 | K13: 1.3333325
H14: 1 | I14: 0.50000042 | J14: 0.75000049 | K14: 1
H15: Zmax
H16: 0.69314676
H17: محدودیت ها
H18: xi-xj-yij=ln(aij) | I18: =LN(J6)-LN(J7)-LN(I11)-LN(C9) -> 2.0172662e-07 | J18: zij ≥ yij | K18: =ABS(LN(I11))-LN(I11) -> 0
I19: =LN(J6)-LN(J8)-LN(J11)-LN(D9) -> 7.0171646e-13 | K19: =ABS(LN(J11))-LN(J11) -> 0
I20: =LN(J6)-LN(J9)-LN(K11)-LN(E9) -> 0 | K20: =ABS(LN(K11))-LN(K11) -> 0
I21: =LN(J7)-LN(J6)-LN(H12)-LN(B10) -> 0 | K21: =ABS(LN(J12))-LN(J12) -> 1.3862934
I22: =LN(J7)-LN(J8)-LN(J12)-LN(D10) -> 1.478373e-12 | K22: =ABS(LN(K12))-LN(K12) -> 0
I23: =LN(J7)-LN(J9)-LN(K12)-LN(E10) -> 0 | K23: =ABS(LN(K13))-LN(K13) -> 0
I24: =LN(J8)-LN(J6)-LN(H13)-LN(B11) -> 0 | J24: zij ≥ yji | K24: =ABS(LN(I11))-LN(H12) -> 1.3862945
I25: =LN(J8)-LN(J7)-LN(I13)-LN(C11) -> -6.3763265e-07 | K25: =ABS(LN(J11))-LN(H13) -> 1.3145365e-06
I26: =LN(J8)-LN(J9)-LN(K13)-LN(E11) -> 0 | K26: =ABS(LN(K11))-LN(H14) -> 0
I27: =LN(J9)-LN(J6)-LN(H14)-LN(B12) -> 0 | K27: =ABS(LN(J12))-LN(I13) -> -6.3763117e-07
I28: =LN(J9)-LN(J7)-LN(I14)-LN(C12) -> -6.3763458e-07 | K28: =ABS(LN(K12))-LN(I14) -> 1.3862933
I29: =LN(J9)-LN(J8)-LN(J14)-LN(D12) -> 6.9899642e-13 | K29: =ABS(LN(K13))-LN(J14) -> 0.57536283
H30: x1 = 0 | I30: =LN(J6) -> 0 | J30: zij ≥ 0 | K30: =ABS(LN(I11)) -> 0.69314717
H31: xi-xj ≥ 0 | I31: =LN(J6)-LN(J8) -> 0.40546577 | K31: =ABS(LN(J11)) -> 6.5726789e-07
I32: =LN(J7)-LN(J8) -> 0.40546557 | K32: =ABS(LN(K11)) -> 0
I33: =LN(J7)-LN(J9) -> -1.9279529e-07 | K33: =ABS(LN(J12)) -> 0.69314672
I34: =ABS(LN(I11))+ABS(LN(J11))+ABS(LN(K11))+ABS(LN(J12))+ABS(LN(K12))+ABS(LN(K13))-I3 -> 0.69314528 | K34: =ABS(LN(K12)) -> 0.69314699
H35: zmax ≥ zij | I35: =$H$16-ABS(LN(I11)) -> -4.1074884e-07 | K35: =ABS(LN(K13)) -> 0.28768142
I36: =$H$16-ABS(LN(J11)) -> 0.6931461 | J36: zmax ≥ 0 | K36: =H16 -> 0.69314676
I37: =$H$16-ABS(LN(K11)) -> 0.69314676
I38: =$H$16-ABS(LN(J12)) -> 4.4791658e-08
I39: =$H$16-ABS(LN(K12)) -> -2.2688488e-07
I40: =$H$16-ABS(LN(K13)) -> 0.40546535

Sheet Q6
B3: روش وزن دهی
B4: بردار ویژه | C4: مجموع سطری | D4: مجموع ستونی | E4: میانگین حسابی | F4: میانگین هندسی | G4: کمترین مجذورات (LSM) | H4: DEAHP | I4: برنامه‌ریزی خطی (LPM) مرحله اول | J4: برنامه‌ریزی خطی (LPM) مرحله دوم
A5: w1 | B5: {=TRANSPOSE(_xlfn.ANCHORARRAY('Q1'!R6))} -> #NAME? | C5: {='Q2'!I4:I7} -> 0.21052632 | D5: {='Q2'!I10:I13} -> 0.24561404 | E5: {='Q2'!M17:M20} -> 0.21951346 | F5: {='Q2'!I23:I26} -> 0.24154154 | G5: {=TRANSPOSE('Q3'!H10:K10)} -> 0.22148601 | H5: {='Q4'!U9:U12} -> 0.28125 | I5: {='Q5-1'!K6:K9} -> 0.24999993 | J5: {='Q5-2'!K6:K9} -> 0.27272732
A6: w2 | B6: #NAME? | C6: 0.34210526 | D6: 0.20175439 | E6: 0.31402692 | F6: 0.34159132 | G6: 0.2802394 | H6: 0.28125 | I6: 0.3750002 | J6: 0.27272727
A7: w3 | B7: #NAME? | C7: 0.13157895 | D7: 0.39473684 | E7: 0.13245342 | F7: 0.14985315 | G7: 0.13543652 | H7: 0.15625 | I7: 0.12499995 | J7: 0.18181809
A8: w4 | B8: #NAME? | C8: 0.31578947 | D8: 0.15789474 | E8: 0.33400621 | F8: 0.36706376 | G8: 0.36283807 | H8: 0.28125 | I8: 0.24999993 | J8: 0.27272732
